Workbook

Sheet Read me
A1: The dyadic prime difference table
A2: Reconstruction of the object discussed in dyadic-table-v2.md and its addendum.
A4: What it is
A5: For each regime r, count the primes in the half-open interval (2^(r-1), 2^r].
A6: Then take repeated finite differences. Cell (r, d) is the d-th difference at regime r.
A7: Composite counts are everything else in the same interval: 2^(r-1) minus the prime count.
A9: Sheets
A10: Counts | B10: Prime and composite counts per regime, and the interval total 2^(r-1).
A11: Prime differences | B11: The difference table. Column d=0 is the counts; every other cell is a formula.
A12: Composite differences | B12: Same construction on the composite counts.
A13: Zeros and repeats | B13: The four zero cells, the four repeats that produce them, and the identity at each.
A15: Colour legend
A16: Blue text | B16: Hardcoded input. Only the prime counts in column B of Counts.
A17: Green text | B17: Link to another sheet.
A18: Black text | B18: Formula.
A19: Yellow fill | B19: A cell referred to in the papers: the four zeros, and their source repeats.
A21: Range and precision
A22: r runs 1 to 54, d runs 0 to 30. The cutoff is not arbitrary: a spreadsheet stores integers
A23: only about 15 significant digits. At r=50 the largest value here is 2^49, and every value is
A24: exact — verified cell by cell against integer arithmetic. The papers used r to 60, depth to 54.
A26: Source of the counts
A27: pi(2^n) computed with primecountpy (Kim Walisch, primecount), n = 0..60.
A28: Reproduce with: import primecountpy as pc; [pc.prime_pi(2**n) for n in range(61)]
A30: What to look at
A31: Four cells in the prime table are exactly zero: (2,1), (4,1), (8,3), (20,6), and no others
A32: anywhere to r=60, depth 54. Two are trivial. (8,3) sits on the mod-6 lattice diagonal r=2d+2,
A33: where a zero is structurally available. (20,6) is the only cell trivial in neither sense.
A34: At each of the four, the composite cell equals 2^(r-d-1) exactly. See Zeros and repeats.

Sheet Counts
A1: regime r | B1: primes in (2^(r-1), 2^r] | C1: composites in same interval | D1: interval total 2^(r-1) | E1: check: primes + composites - total
A2: 1 | B2: 1 | C2: =D2-B2 -> 0 | D2: =2^(1-1) -> 1 | E2: =B2+C2-D2 -> 0
A3: 2 | B3: 1 | C3: =D3-B3 -> 1 | D3: =2^(2-1) -> 2 | E3: =B3+C3-D3 -> 0
A4: 3 | B4: 2 | C4: =D4-B4 -> 2 | D4: =2^(3-1) -> 4 | E4: =B4+C4-D4 -> 0
A5: 4 | B5: 2 | C5: =D5-B5 -> 6 | D5: =2^(4-1) -> 8 | E5: =B5+C5-D5 -> 0
A6: 5 | B6: 5 | C6: =D6-B6 -> 11 | D6: =2^(5-1) -> 16 | E6: =B6+C6-D6 -> 0
A7: 6 | B7: 7 | C7: =D7-B7 -> 25 | D7: =2^(6-1) -> 32 | E7: =B7+C7-D7 -> 0
A8: 7 | B8: 13 | C8: =D8-B8 -> 51 | D8: =2^(7-1) -> 64 | E8: =B8+C8-D8 -> 0
A9: 8 | B9: 23 | C9: =D9-B9 -> 105 | D9: =2^(8-1) -> 128 | E9: =B9+C9-D9 -> 0
A10: 9 | B10: 43 | C10: =D10-B10 -> 213 | D10: =2^(9-1) -> 256 | E10: =B10+C10-D10 -> 0
A11: 10 | B11: 75 | C11: =D11-B11 -> 437 | D11: =2^(10-1) -> 512 | E11: =B11+C11-D11 -> 0
A12: 11 | B12: 137 | C12: =D12-B12 -> 887 | D12: =2^(11-1) -> 1024 | E12: =B12+C12-D12 -> 0
A13: 12 | B13: 255 | C13: =D13-B13 -> 1793 | D13: =2^(12-1) -> 2048 | E13: =B13+C13-D13 -> 0
A14: 13 | B14: 464 | C14: =D14-B14 -> 3632 | D14: =2^(13-1) -> 4096 | E14: =B14+C14-D14 -> 0
A15: 14 | B15: 872 | C15: =D15-B15 -> 7320 | D15: =2^(14-1) -> 8192 | E15: =B15+C15-D15 -> 0
A16: 15 | B16: 1612 | C16: =D16-B16 -> 14772 | D16: =2^(15-1) -> 16384 | E16: =B16+C16-D16 -> 0
A17: 16 | B17: 3030 | C17: =D17-B17 -> 29738 | D17: =2^(16-1) -> 32768 | E17: =B17+C17-D17 -> 0
A18: 17 | B18: 5709 | C18: =D18-B18 -> 59827 | D18: =2^(17-1) -> 65536 | E18: =B18+C18-D18 -> 0
A19: 18 | B19: 10749 | C19: =D19-B19 -> 120323 | D19: =2^(18-1) -> 131072 | E19: =B19+C19-D19 -> 0
A20: 19 | B20: 20390 | C20: =D20-B20 -> 241754 | D20: =2^(19-1) -> 262144 | E20: =B20+C20-D20 -> 0
A21: 20 | B21: 38635 | C21: =D21-B21 -> 485653 | D21: =2^(20-1) -> 524288 | E21: =B21+C21-D21 -> 0
A22: 21 | B22: 73586 | C22: =D22-B22 -> 974990 | D22: =2^(21-1) -> 1048576 | E22: =B22+C22-D22 -> 0
A23: 22 | B23: 140336 | C23: =D23-B23 -> 1956816 | D23: =2^(22-1) -> 2097152 | E23: =B23+C23-D23 -> 0
A24: 23 | B24: 268216 | C24: =D24-B24 -> 3926088 | D24: =2^(23-1) -> 4194304 | E24: =B24+C24-D24 -> 0
A25: 24 | B25: 513708 | C25: =D25-B25 -> 7874900 | D25: =2^(24-1) -> 8388608 | E25: =B25+C25-D25 -> 0
A26: 25 | B26: 985818 | C26: =D26-B26 -> 15791398 | D26: =2^(25-1) -> 16777216 | E26: =B26+C26-D26 -> 0
A27: 26 | B27: 1894120 | C27: =D27-B27 -> 31660312 | D27: =2^(26-1) -> 33554432 | E27: =B27+C27-D27 -> 0
A28: 27 | B28: 3645744 | C28: =D28-B28 -> 63463120 | D28: =2^(27-1) -> 67108864 | E28: =B28+C28-D28 -> 0
A29: 28 | B29: 7027290 | C29: =D29-B29 -> 127190438 | D29: =2^(28-1) -> 134217728 | E29: =B29+C29-D29 -> 0
A30: 29 | B30: 13561907 | C30: =D30-B30 -> 254873549 | D30: =2^(29-1) -> 268435456 | E30: =B30+C30-D30 -> 0
A31: 30 | B31: 26207278 | C31: =D31-B31 -> 510663634 | D31: =2^(30-1) -> 536870912 | E31: =B31+C31-D31 -> 0
A32: 31 | B32: 50697537 | C32: =D32-B32 -> 1023044287 | D32: =2^(31-1) -> 1073741824 | E32: =B32+C32-D32 -> 0
A33: 32 | B33: 98182656 | C33: =D33-B33 -> 2049300992 | D33: =2^(32-1) -> 2147483648 | E33: =B33+C33-D33 -> 0
A34: 33 | B34: 190335585 | C34: =D34-B34 -> 4104631711 | D34: =2^(33-1) -> 4294967296 | E34: =B34+C34-D34 -> 0
A35: 34 | B35: 369323305 | C35: =D35-B35 -> 8220611287 | D35: =2^(34-1) -> 8589934592 | E35: =B35+C35-D35 -> 0
A36: 35 | B36: 717267168 | C36: =D36-B36 -> 16462602016 | D36: =2^(35-1) -> 17179869184 | E36: =B36+C36-D36 -> 0
A37: 36 | B37: 1394192236 | C37: =D37-B37 -> 32965546132 | D37: =2^(36-1) -> 34359738368 | E37: =B37+C37-D37 -> 0
A38: 37 | B38: 2712103833 | C38: =D38-B38 -> 66007372903 | D38: =2^(37-1) -> 68719476736 | E38: =B38+C38-D38 -> 0
A39: 38 | B39: 5279763824 | C39: =D39-B39 -> 132159189648 | D39: =2^(38-1) -> 137438953472 | E39: =B39+C39-D39 -> 0
A40: 39 | B40: 10285641778 | C40: =D40-B40 -> 264592265166 | D40: =2^(39-1) -> 274877906944 | E40: =B40+C40-D40 -> 0
...

Sheet Prime differences
A1: r \ d | B1: 0 | C1: 1 | D1: 2 | E1: 3 | F1: 4 | G1: 5 | H1: 6 | I1: 7 | J1: 8 | K1: 9 | L1: 10 | M1: 11 | N1: 12 | O1: 13 | P1: 14 | Q1: 15 | R1: 16 | S1: 17 | T1: 18 | U1: 19 | V1: 20 | W1: 21 | X1: 22 | Y1: 23 | Z1: 24 | AA1: 25 | AB1: 26 | AC1: 27 | AD1: 28 | AE1: 29 | AF1: 30
A2: 1 | B2: =Counts!B2 -> 1
A3: 2 | B3: =Counts!B3 -> 1 | C3: =B3-B2 -> 0
A4: 3 | B4: =Counts!B4 -> 2 | C4: =B4-B3 -> 1 | D4: =C4-C3 -> 1
A5: 4 | B5: =Counts!B5 -> 2 | C5: =B5-B4 -> 0 | D5: =C5-C4 -> -1 | E5: =D5-D4 -> -2
A6: 5 | B6: =Counts!B6 -> 5 | C6: =B6-B5 -> 3 | D6: =C6-C5 -> 3 | E6: =D6-D5 -> 4 | F6: =E6-E5 -> 6
A7: 6 | B7: =Counts!B7 -> 7 | C7: =B7-B6 -> 2 | D7: =C7-C6 -> -1 | E7: =D7-D6 -> -4 | F7: =E7-E6 -> -8 | G7: =F7-F6 -> -14
A8: 7 | B8: =Counts!B8 -> 13 | C8: =B8-B7 -> 6 | D8: =C8-C7 -> 4 | E8: =D8-D7 -> 5 | F8: =E8-E7 -> 9 | G8: =F8-F7 -> 17 | H8: =G8-G7 -> 31
A9: 8 | B9: =Counts!B9 -> 23 | C9: =B9-B8 -> 10 | D9: =C9-C8 -> 4 | E9: =D9-D8 -> 0 | F9: =E9-E8 -> -5 | G9: =F9-F8 -> -14 | H9: =G9-G8 -> -31 | I9: =H9-H8 -> -62
A10: 9 | B10: =Counts!B10 -> 43 | C10: =B10-B9 -> 20 | D10: =C10-C9 -> 10 | E10: =D10-D9 -> 6 | F10: =E10-E9 -> 6 | G10: =F10-F9 -> 11 | H10: =G10-G9 -> 25 | I10: =H10-H9 -> 56 | J10: =I10-I9 -> 118
A11: 10 | B11: =Counts!B11 -> 75 | C11: =B11-B10 -> 32 | D11: =C11-C10 -> 12 | E11: =D11-D10 -> 2 | F11: =E11-E10 -> -4 | G11: =F11-F10 -> -10 | H11: =G11-G10 -> -21 | I11: =H11-H10 -> -46 | J11: =I11-I10 -> -102 | K11: =J11-J10 -> -220
A12: 11 | B12: =Counts!B12 -> 137 | C12: =B12-B11 -> 62 | D12: =C12-C11 -> 30 | E12: =D12-D11 -> 18 | F12: =E12-E11 -> 16 | G12: =F12-F11 -> 20 | H12: =G12-G11 -> 30 | I12: =H12-H11 -> 51 | J12: =I12-I11 -> 97 | ... L12: =K12-K11 -> 419
A13: 12 | B13: =Counts!B13 -> 255 | C13: =B13-B12 -> 118 | D13: =C13-C12 -> 56 | E13: =D13-D12 -> 26 | F13: =E13-E12 -> 8 | G13: =F13-F12 -> -8 | H13: =G13-G12 -> -28 | I13: =H13-H12 -> -58 | J13: =I13-I12 -> -109 | ... M13: =L13-L12 -> -824
A14: 13 | B14: =Counts!B14 -> 464 | C14: =B14-B13 -> 209 | D14: =C14-C13 -> 91 | E14: =D14-D13 -> 35 | F14: =E14-E13 -> 9 | G14: =F14-F13 -> 1 | H14: =G14-G13 -> 9 | I14: =H14-H13 -> 37 | J14: =I14-I13 -> 95 | ... N14: =M14-M13 -> 1639
A15: 14 | B15: =Counts!B15 -> 872 | C15: =B15-B14 -> 408 | D15: =C15-C14 -> 199 | E15: =D15-D14 -> 108 | F15: =E15-E14 -> 73 | G15: =F15-F14 -> 64 | H15: =G15-G14 -> 63 | I15: =H15-H14 -> 54 | J15: =I15-I14 -> 17 | ... O15: =N15-N14 -> -3146
A16: 15 | B16: =Counts!B16 -> 1612 | C16: =B16-B15 -> 740 | D16: =C16-C15 -> 332 | E16: =D16-D15 -> 133 | F16: =E16-E15 -> 25 | G16: =F16-F15 -> -48 | H16: =G16-G15 -> -112 | I16: =H16-H15 -> -175 | J16: =I16-I15 -> -229 | ... P16: =O16-O15 -> 5459
A17: 16 | B17: =Counts!B17 -> 3030 | C17: =B17-B16 -> 1418 | D17: =C17-C16 -> 678 | E17: =D17-D16 -> 346 | F17: =E17-E16 -> 213 | G17: =F17-F16 -> 188 | H17: =G17-G16 -> 236 | I17: =H17-H16 -> 348 | J17: =I17-I16 -> 523 | ... Q17: =P17-P16 -> -7526
A18: 17 | B18: =Counts!B18 -> 5709 | C18: =B18-B17 -> 2679 | D18: =C18-C17 -> 1261 | E18: =D18-D17 -> 583 | F18: =E18-E17 -> 237 | G18: =F18-F17 -> 24 | H18: =G18-G17 -> -164 | I18: =H18-H17 -> -400 | J18: =I18-I17 -> -748 | ... R18: =Q18-Q17 -> 4108
A19: 18 | B19: =Counts!B19 -> 10749 | C19: =B19-B18 -> 5040 | D19: =C19-C18 -> 2361 | E19: =D19-D18 -> 1100 | F19: =E19-E18 -> 517 | G19: =F19-F18 -> 280 | H19: =G19-G18 -> 256 | I19: =H19-H18 -> 420 | J19: =I19-I18 -> 820 | ... S19: =R19-R18 -> 22104
A20: 19 | B20: =Counts!B20 -> 20390 | C20: =B20-B19 -> 9641 | D20: =C20-C19 -> 4601 | E20: =D20-D19 -> 2240 | F20: =E20-E19 -> 1140 | G20: =F20-F19 -> 623 | H20: =G20-G19 -> 343 | I20: =H20-H19 -> 87 | J20: =I20-I19 -> -333 | ... T20: =S20-S19 -> -118794
A21: 20 | B21: =Counts!B21 -> 38635 | C21: =B21-B20 -> 18245 | D21: =C21-C20 -> 8604 | E21: =D21-D20 -> 4003 | F21: =E21-E20 -> 1763 | G21: =F21-F20 -> 623 | H21: =G21-G20 -> 0 | I21: =H21-H20 -> -343 | J21: =I21-I20 -> -430 | ... U21: =T21-T20 -> 402085
A22: 21 | B22: =Counts!B22 -> 73586 | C22: =B22-B21 -> 34951 | D22: =C22-C21 -> 16706 | E22: =D22-D21 -> 8102 | F22: =E22-E21 -> 4099 | G22: =F22-F21 -> 2336 | H22: =G22-G21 -> 1713 | I22: =H22-H21 -> 1713 | J22: =I22-I21 -> 2056 | ... V22: =U22-U21 -> -1125949
A23: 22 | B23: =Counts!B23 -> 140336 | C23: =B23-B22 -> 66750 | D23: =C23-C22 -> 31799 | E23: =D23-D22 -> 15093 | F23: =E23-E22 -> 6991 | G23: =F23-F22 -> 2892 | H23: =G23-G22 -> 556 | I23: =H23-H22 -> -1157 | J23: =I23-I22 -> -2870 | ... W23: =V23-V22 -> 2785278
A24: 23 | B24: =Counts!B24 -> 268216 | C24: =B24-B23 -> 127880 | D24: =C24-C23 -> 61130 | E24: =D24-D23 -> 29331 | F24: =E24-E23 -> 14238 | G24: =F24-F23 -> 7247 | H24: =G24-G23 -> 4355 | I24: =H24-H23 -> 3799 | J24: =I24-I23 -> 4956 | ... X24: =W24-W23 -> -6203978
A25: 24 | B25: =Counts!B25 -> 513708 | C25: =B25-B24 -> 245492 | D25: =C25-C24 -> 117612 | E25: =D25-D24 -> 56482 | F25: =E25-E24 -> 27151 | G25: =F25-F24 -> 12913 | H25: =G25-G24 -> 5666 | I25: =H25-H24 -> 1311 | J25: =I25-I24 -> -2488 | ... Y25: =X25-X24 -> 12388469
A26: 25 | B26: =Counts!B26 -> 985818 | C26: =B26-B25 -> 472110 | D26: =C26-C25 -> 226618 | E26: =D26-D25 -> 109006 | F26: =E26-E25 -> 52524 | G26: =F26-F25 -> 25373 | H26: =G26-G25 -> 12460 | I26: =H26-H25 -> 6794 | J26: =I26-I25 -> 5483 | ... Z26: =Y26-Y25 -> -21450731
A27: 26 | B27: =Counts!B27 -> 1894120 | C27: =B27-B26 -> 908302 | D27: =C27-C26 -> 436192 | E27: =D27-D26 -> 209574 | F27: =E27-E26 -> 100568 | G27: =F27-F26 -> 48044 | H27: =G27-G26 -> 22671 | I27: =H27-H26 -> 10211 | J27: =I27-I26 -> 3417 | ... AA27: =Z27-Z26 -> 28716554
A28: 27 | B28: =Counts!B28 -> 3645744 | C28: =B28-B27 -> 1751624 | D28: =C28-C27 -> 843322 | E28: =D28-D27 -> 407130 | F28: =E28-E27 -> 197556 | G28: =F28-F27 -> 96988 | H28: =G28-G27 -> 48944 | I28: =H28-H27 -> 26273 | J28: =I28-I27 -> 16062 | ... AB28: =AA28-AA27 -> -13384036
A29: 28 | B29: =Counts!B29 -> 7027290 | C29: =B29-B28 -> 3381546 | D29: =C29-C28 -> 1629922 | E29: =D29-D28 -> 786600 | F29: =E29-E28 -> 379470 | G29: =F29-F28 -> 181914 | H29: =G29-G28 -> 84926 | I29: =H29-H28 -> 35982 | J29: =I29-I28 -> 9709 | ... AC29: =AB29-AB28 -> -90944359
A30: 29 | B30: =Counts!B30 -> 13561907 | C30: =B30-B29 -> 6534617 | D30: =C30-C29 -> 3153071 | E30: =D30-D29 -> 1523149 | F30: =E30-E29 -> 736549 | G30: =F30-F29 -> 357079 | H30: =G30-G29 -> 175165 | I30: =H30-H29 -> 90239 | J30: =I30-I29 -> 54257 | ... AD30: =AC30-AC29 -> 467395691
A31: 30 | B31: =Counts!B31 -> 26207278 | C31: =B31-B30 -> 12645371 | D31: =C31-C30 -> 6110754 | E31: =D31-D30 -> 2957683 | F31: =E31-E30 -> 1434534 | G31: =F31-F30 -> 697985 | H31: =G31-G30 -> 340906 | I31: =H31-H30 -> 165741 | J31: =I31-I30 -> 75502 | ... AE31: =AD31-AD30 -> -1579268857
A32: 31 | B32: =Counts!B32 -> 50697537 | C32: =B32-B31 -> 24490259 | D32: =C32-C31 -> 11844888 | E32: =D32-D31 -> 5734134 | F32: =E32-E31 -> 2776451 | G32: =F32-F31 -> 1341917 | H32: =G32-G31 -> 643932 | I32: =H32-H31 -> 303026 | J32: =I32-I31 -> 137285 | ... AF32: =AE32-AE31 -> 4533953516
A33: 32 | B33: =Counts!B33 -> 98182656 | C33: =B33-B32 -> 47485119 | D33: =C33-C32 -> 22994860 | E33: =D33-D32 -> 11149972 | F33: =E33-E32 -> 5415838 | G33: =F33-F32 -> 2639387 | H33: =G33-G32 -> 1297470 | I33: =H33-H32 -> 653538 | J33: =I33-I32 -> 350512 | ... AF33: =AE33-AE32 -> -7345558455
A34: 33 | B34: =Counts!B34 -> 190335585 | C34: =B34-B33 -> 92152929 | D34: =C34-C33 -> 44667810 | E34: =D34-D33 -> 21672950 | F34: =E34-E33 -> 10522978 | G34: =F34-F33 -> 5107140 | H34: =G34-G33 -> 2467753 | I34: =H34-H33 -> 1170283 | J34: =I34-I33 -> 516745 | ... AF34: =AE34-AE33 -> 10111196034
A35: 34 | B35: =Counts!B35 -> 369323305 | C35: =B35-B34 -> 178987720 | D35: =C35-C34 -> 86834791 | E35: =D35-D34 -> 42166981 | F35: =E35-E34 -> 20494031 | G35: =F35-F34 -> 9971053 | H35: =G35-G34 -> 4863913 | I35: =H35-H34 -> 2396160 | J35: =I35-I34 -> 1225877 | ... AF35: =AE35-AE34 -> -12645854833
A36: 35 | B36: =Counts!B36 -> 717267168 | C36: =B36-B35 -> 347943863 | D36: =C36-C35 -> 168956143 | E36: =D36-D35 -> 82121352 | F36: =E36-E35 -> 39954371 | G36: =F36-F35 -> 19460340 | H36: =G36-G35 -> 9489287 | I36: =H36-H35 -> 4625374 | J36: =I36-I35 -> 2229214 | ... AF36: =AE36-AE35 -> 15010795710
A37: 36 | B37: =Counts!B37 -> 1394192236 | C37: =B37-B36 -> 676925068 | D37: =C37-C36 -> 328981205 | E37: =D37-D36 -> 160025062 | F37: =E37-E36 -> 77903710 | G37: =F37-F36 -> 37949339 | H37: =G37-G36 -> 18488999 | I37: =H37-H36 -> 8999712 | J37: =I37-I36 -> 4374338 | ... AF37: =AE37-AE36 -> -17130013871
A38: 37 | B38: =Counts!B38 -> 2712103833 | C38: =B38-B37 -> 1317911597 | D38: =C38-C37 -> 640986529 | E38: =D38-D37 -> 312005324 | F38: =E38-E37 -> 151980262 | G38: =F38-F37 -> 74076552 | H38: =G38-G37 -> 36127213 | I38: =H38-H37 -> 17638214 | J38: =I38-I37 -> 8638502 | ... AF38: =AE38-AE37 -> 17970444330
A39: 38 | B39: =Counts!B39 -> 5279763824 | C39: =B39-B38 -> 2567659991 | D39: =C39-C38 -> 1249748394 | E39: =D39-D38 -> 608761865 | F39: =E39-E38 -> 296756541 | G39: =F39-F38 -> 144776279 | H39: =G39-G38 -> 70699727 | I39: =H39-H38 -> 34572514 | J39: =I39-I38 -> 16934300 | ... AF39: =AE39-AE38 -> -14823565702
A40: 39 | B40: =Counts!B40 -> 10285641778 | C40: =B40-B39 -> 5005877954 | D40: =C40-C39 -> 2438217963 | E40: =D40-D39 -> 1188469569 | F40: =E40-E39 -> 579707704 | G40: =F40-F39 -> 282951163 | H40: =G40-G39 -> 138174884 | I40: =H40-H39 -> 67475157 | J40: =I40-I39 -> 32902643 | ... AF40: =AE40-AE39 -> 3626768509
...

Sheet Composite differences
A1: r \ d | B1: 0 | C1: 1 | D1: 2 | E1: 3 | F1: 4 | G1: 5 | H1: 6 | I1: 7 | J1: 8 | K1: 9 | L1: 10 | M1: 11 | N1: 12 | O1: 13 | P1: 14 | Q1: 15 | R1: 16 | S1: 17 | T1: 18 | U1: 19 | V1: 20 | W1: 21 | X1: 22 | Y1: 23 | Z1: 24 | AA1: 25 | AB1: 26 | AC1: 27 | AD1: 28 | AE1: 29 | AF1: 30
A2: 1 | B2: =Counts!C2 -> 0
A3: 2 | B3: =Counts!C3 -> 1 | C3: =B3-B2 -> 1
A4: 3 | B4: =Counts!C4 -> 2 | C4: =B4-B3 -> 1 | D4: =C4-C3 -> 0
A5: 4 | B5: =Counts!C5 -> 6 | C5: =B5-B4 -> 4 | D5: =C5-C4 -> 3 | E5: =D5-D4 -> 3
A6: 5 | B6: =Counts!C6 -> 11 | C6: =B6-B5 -> 5 | D6: =C6-C5 -> 1 | E6: =D6-D5 -> -2 | F6: =E6-E5 -> -5
A7: 6 | B7: =Counts!C7 -> 25 | C7: =B7-B6 -> 14 | D7: =C7-C6 -> 9 | E7: =D7-D6 -> 8 | F7: =E7-E6 -> 10 | G7: =F7-F6 -> 15
A8: 7 | B8: =Counts!C8 -> 51 | C8: =B8-B7 -> 26 | D8: =C8-C7 -> 12 | E8: =D8-D7 -> 3 | F8: =E8-E7 -> -5 | G8: =F8-F7 -> -15 | H8: =G8-G7 -> -30
A9: 8 | B9: =Counts!C9 -> 105 | C9: =B9-B8 -> 54 | D9: =C9-C8 -> 28 | E9: =D9-D8 -> 16 | F9: =E9-E8 -> 13 | G9: =F9-F8 -> 18 | H9: =G9-G8 -> 33 | I9: =H9-H8 -> 63
A10: 9 | B10: =Counts!C10 -> 213 | C10: =B10-B9 -> 108 | D10: =C10-C9 -> 54 | E10: =D10-D9 -> 26 | F10: =E10-E9 -> 10 | G10: =F10-F9 -> -3 | H10: =G10-G9 -> -21 | I10: =H10-H9 -> -54 | J10: =I10-I9 -> -117
A11: 10 | B11: =Counts!C11 -> 437 | C11: =B11-B10 -> 224 | D11: =C11-C10 -> 116 | E11: =D11-D10 -> 62 | F11: =E11-E10 -> 36 | G11: =F11-F10 -> 26 | H11: =G11-G10 -> 29 | I11: =H11-H10 -> 50 | J11: =I11-I10 -> 104 | K11: =J11-J10 -> 221
A12: 11 | B12: =Counts!C12 -> 887 | C12: =B12-B11 -> 450 | D12: =C12-C11 -> 226 | E12: =D12-D11 -> 110 | F12: =E12-E11 -> 48 | G12: =F12-F11 -> 12 | H12: =G12-G11 -> -14 | I12: =H12-H11 -> -43 | J12: =I12-I11 -> -93 | ... L12: =K12-K11 -> -418
A13: 12 | B13: =Counts!C13 -> 1793 | C13: =B13-B12 -> 906 | D13: =C13-C12 -> 456 | E13: =D13-D12 -> 230 | F13: =E13-E12 -> 120 | G13: =F13-F12 -> 72 | H13: =G13-G12 -> 60 | I13: =H13-H12 -> 74 | J13: =I13-I12 -> 117 | ... M13: =L13-L12 -> 825
A14: 13 | B14: =Counts!C14 -> 3632 | C14: =B14-B13 -> 1839 | D14: =C14-C13 -> 933 | E14: =D14-D13 -> 477 | F14: =E14-E13 -> 247 | G14: =F14-F13 -> 127 | H14: =G14-G13 -> 55 | I14: =H14-H13 -> -5 | J14: =I14-I13 -> -79 | ... N14: =M14-M13 -> -1638
A15: 14 | B15: =Counts!C15 -> 7320 | C15: =B15-B14 -> 3688 | D15: =C15-C14 -> 1849 | E15: =D15-D14 -> 916 | F15: =E15-E14 -> 439 | G15: =F15-F14 -> 192 | H15: =G15-G14 -> 65 | I15: =H15-H14 -> 10 | J15: =I15-I14 -> 15 | ... O15: =N15-N14 -> 3147
A16: 15 | B16: =Counts!C16 -> 14772 | C16: =B16-B15 -> 7452 | D16: =C16-C15 -> 3764 | E16: =D16-D15 -> 1915 | F16: =E16-E15 -> 999 | G16: =F16-F15 -> 560 | H16: =G16-G15 -> 368 | I16: =H16-H15 -> 303 | J16: =I16-I15 -> 293 | ... P16: =O16-O15 -> -5458
A17: 16 | B17: =Counts!C17 -> 29738 | C17: =B17-B16 -> 14966 | D17: =C17-C16 -> 7514 | E17: =D17-D16 -> 3750 | F17: =E17-E16 -> 1835 | G17: =F17-F16 -> 836 | H17: =G17-G16 -> 276 | I17: =H17-H16 -> -92 | J17: =I17-I16 -> -395 | ... Q17: =P17-P16 -> 7527
A18: 17 | B18: =Counts!C18 -> 59827 | C18: =B18-B17 -> 30089 | D18: =C18-C17 -> 15123 | E18: =D18-D17 -> 7609 | F18: =E18-E17 -> 3859 | G18: =F18-F17 -> 2024 | H18: =G18-G17 -> 1188 | I18: =H18-H17 -> 912 | J18: =I18-I17 -> 1004 | ... R18: =Q18-Q17 -> -4107
A19: 18 | B19: =Counts!C19 -> 120323 | C19: =B19-B18 -> 60496 | D19: =C19-C18 -> 30407 | E19: =D19-D18 -> 15284 | F19: =E19-E18 -> 7675 | G19: =F19-F18 -> 3816 | H19: =G19-G18 -> 1792 | I19: =H19-H18 -> 604 | J19: =I19-I18 -> -308 | ... S19: =R19-R18 -> -22103
A20: 19 | B20: =Counts!C20 -> 241754 | C20: =B20-B19 -> 121431 | D20: =C20-C19 -> 60935 | E20: =D20-D19 -> 30528 | F20: =E20-E19 -> 15244 | G20: =F20-F19 -> 7569 | H20: =G20-G19 -> 3753 | I20: =H20-H19 -> 1961 | J20: =I20-I19 -> 1357 | ... T20: =S20-S19 -> 118795
A21: 20 | B21: =Counts!C21 -> 485653 | C21: =B21-B20 -> 243899 | D21: =C21-C20 -> 122468 | E21: =D21-D20 -> 61533 | F21: =E21-E20 -> 31005 | G21: =F21-F20 -> 15761 | H21: =G21-G20 -> 8192 | I21: =H21-H20 -> 4439 | J21: =I21-I20 -> 2478 | ... U21: =T21-T20 -> -402084
A22: 21 | B22: =Counts!C22 -> 974990 | C22: =B22-B21 -> 489337 | D22: =C22-C21 -> 245438 | E22: =D22-D21 -> 122970 | F22: =E22-E21 -> 61437 | G22: =F22-F21 -> 30432 | H22: =G22-G21 -> 14671 | I22: =H22-H21 -> 6479 | J22: =I22-I21 -> 2040 | ... V22: =U22-U21 -> 1125950
A23: 22 | B23: =Counts!C23 -> 1956816 | C23: =B23-B22 -> 981826 | D23: =C23-C22 -> 492489 | E23: =D23-D22 -> 247051 | F23: =E23-E22 -> 124081 | G23: =F23-F22 -> 62644 | H23: =G23-G22 -> 32212 | I23: =H23-H22 -> 17541 | J23: =I23-I22 -> 11062 | ... W23: =V23-V22 -> -2785277
A24: 23 | B24: =Counts!C24 -> 3926088 | C24: =B24-B23 -> 1969272 | D24: =C24-C23 -> 987446 | E24: =D24-D23 -> 494957 | F24: =E24-E23 -> 247906 | G24: =F24-F23 -> 123825 | H24: =G24-G23 -> 61181 | I24: =H24-H23 -> 28969 | J24: =I24-I23 -> 11428 | ... X24: =W24-W23 -> 6203979
A25: 24 | B25: =Counts!C25 -> 7874900 | C25: =B25-B24 -> 3948812 | D25: =C25-C24 -> 1979540 | E25: =D25-D24 -> 992094 | F25: =E25-E24 -> 497137 | G25: =F25-F24 -> 249231 | H25: =G25-G24 -> 125406 | I25: =H25-H24 -> 64225 | J25: =I25-I24 -> 35256 | ... Y25: =X25-X24 -> -12388468
A26: 25 | B26: =Counts!C26 -> 15791398 | C26: =B26-B25 -> 7916498 | D26: =C26-C25 -> 3967686 | E26: =D26-D25 -> 1988146 | F26: =E26-E25 -> 996052 | G26: =F26-F25 -> 498915 | H26: =G26-G25 -> 249684 | I26: =H26-H25 -> 124278 | J26: =I26-I25 -> 60053 | ... Z26: =Y26-Y25 -> 21450732
A27: 26 | B27: =Counts!C27 -> 31660312 | C27: =B27-B26 -> 15868914 | D27: =C27-C26 -> 7952416 | E27: =D27-D26 -> 3984730 | F27: =E27-E26 -> 1996584 | G27: =F27-F26 -> 1000532 | H27: =G27-G26 -> 501617 | I27: =H27-H26 -> 251933 | J27: =I27-I26 -> 127655 | ... AA27: =Z27-Z26 -> -28716553
A28: 27 | B28: =Counts!C28 -> 63463120 | C28: =B28-B27 -> 31802808 | D28: =C28-C27 -> 15933894 | E28: =D28-D27 -> 7981478 | F28: =E28-E27 -> 3996748 | G28: =F28-F27 -> 2000164 | H28: =G28-G27 -> 999632 | I28: =H28-H27 -> 498015 | J28: =I28-I27 -> 246082 | ... AB28: =AA28-AA27 -> 13384037
A29: 28 | B29: =Counts!C29 -> 127190438 | C29: =B29-B28 -> 63727318 | D29: =C29-C28 -> 31924510 | E29: =D29-D28 -> 15990616 | F29: =E29-E28 -> 8009138 | G29: =F29-F28 -> 4012390 | H29: =G29-G28 -> 2012226 | I29: =H29-H28 -> 1012594 | J29: =I29-I28 -> 514579 | ... AC29: =AB29-AB28 -> 90944360
A30: 29 | B30: =Counts!C30 -> 254873549 | C30: =B30-B29 -> 127683111 | D30: =C30-C29 -> 63955793 | E30: =D30-D29 -> 32031283 | F30: =E30-E29 -> 16040667 | G30: =F30-F29 -> 8031529 | H30: =G30-G29 -> 4019139 | I30: =H30-H29 -> 2006913 | J30: =I30-I29 -> 994319 | ... AD30: =AC30-AC29 -> -467395690
A31: 30 | B31: =Counts!C31 -> 510663634 | C31: =B31-B30 -> 255790085 | D31: =C31-C30 -> 128106974 | E31: =D31-D30 -> 64151181 | F31: =E31-E30 -> 32119898 | G31: =F31-F30 -> 16079231 | H31: =G31-G30 -> 8047702 | I31: =H31-H30 -> 4028563 | J31: =I31-I30 -> 2021650 | ... AE31: =AD31-AD30 -> 1579268858
A32: 31 | B32: =Counts!C32 -> 1023044287 | C32: =B32-B31 -> 512380653 | D32: =C32-C31 -> 256590568 | E32: =D32-D31 -> 128483594 | F32: =E32-E31 -> 64332413 | G32: =F32-F31 -> 32212515 | H32: =G32-G31 -> 16133284 | I32: =H32-H31 -> 8085582 | J32: =I32-I31 -> 4057019 | ... AF32: =AE32-AE31 -> -4533953515
A33: 32 | B33: =Counts!C33 -> 2049300992 | C33: =B33-B32 -> 1026256705 | D33: =C33-C32 -> 513876052 | E33: =D33-D32 -> 257285484 | F33: =E33-E32 -> 128801890 | G33: =F33-F32 -> 64469477 | H33: =G33-G32 -> 32256962 | I33: =H33-H32 -> 16123678 | J33: =I33-I32 -> 8038096 | ... AF33: =AE33-AE32 -> 7345558457
A34: 33 | B34: =Counts!C34 -> 4104631711 | C34: =B34-B33 -> 2055330719 | D34: =C34-C33 -> 1029074014 | E34: =D34-D33 -> 515197962 | F34: =E34-E33 -> 257912478 | G34: =F34-F33 -> 129110588 | H34: =G34-G33 -> 64641111 | I34: =H34-H33 -> 32384149 | J34: =I34-I33 -> 16260471 | ... AF34: =AE34-AE33 -> -10111196030
A35: 34 | B35: =Counts!C35 -> 8220611287 | C35: =B35-B34 -> 4115979576 | D35: =C35-C34 -> 2060648857 | E35: =D35-D34 -> 1031574843 | F35: =E35-E34 -> 516376881 | G35: =F35-F34 -> 258464403 | H35: =G35-G34 -> 129353815 | I35: =H35-H34 -> 64712704 | J35: =I35-I34 -> 32328555 | ... AF35: =AE35-AE34 -> 12645854841
A36: 35 | B36: =Counts!C36 -> 16462602016 | C36: =B36-B35 -> 8241990729 | D36: =C36-C35 -> 4126011153 | E36: =D36-D35 -> 2065362296 | F36: =E36-E35 -> 1033787453 | G36: =F36-F35 -> 517410572 | H36: =G36-G35 -> 258946169 | I36: =H36-H35 -> 129592354 | J36: =I36-I35 -> 64879650 | ... AF36: =AE36-AE35 -> -15010795694
A37: 36 | B37: =Counts!C37 -> 32965546132 | C37: =B37-B36 -> 16502944116 | D37: =C37-C36 -> 8260953387 | E37: =D37-D36 -> 4134942234 | F37: =E37-E36 -> 2069579938 | G37: =F37-F36 -> 1035792485 | H37: =G37-G36 -> 518381913 | I37: =H37-H36 -> 259435744 | J37: =I37-I36 -> 129843390 | ... AF37: =AE37-AE36 -> 17130013903
A38: 37 | B38: =Counts!C38 -> 66007372903 | C38: =B38-B37 -> 33041826771 | D38: =C38-C37 -> 16538882655 | E38: =D38-D37 -> 8277929268 | F38: =E38-E37 -> 4142987034 | G38: =F38-F37 -> 2073407096 | H38: =G38-G37 -> 1037614611 | I38: =H38-H37 -> 519232698 | J38: =I38-I37 -> 259796954 | ... AF38: =AE38-AE37 -> -17970444266
A39: 38 | B39: =Counts!C39 -> 132159189648 | C39: =B39-B38 -> 66151816745 | D39: =C39-C38 -> 33109989974 | E39: =D39-D38 -> 16571107319 | F39: =E39-E38 -> 8293178051 | G39: =F39-F38 -> 4150191017 | H39: =G39-G38 -> 2076783921 | I39: =H39-H38 -> 1039169310 | J39: =I39-I38 -> 519936612 | ... AF39: =AE39-AE38 -> 14823565830
A40: 39 | B40: =Counts!C40 -> 264592265166 | C40: =B40-B39 -> 132433075518 | D40: =C40-C39 -> 66281258773 | E40: =D40-D39 -> 33171268799 | F40: =E40-E39 -> 16600161480 | G40: =F40-F39 -> 8306983429 | H40: =G40-G39 -> 4156792412 | I40: =H40-H39 -> 2080008491 | J40: =I40-I39 -> 1040839181 | ... AF40: =AE40-AE39 -> -3626768253
...

Sheet Zeros and repeats
A1: The four zeros
A3: cell (r, d) | B3: prime cell | C3: composite cell | D3: 2^(r-d-1) | E3: window (regimes) | F3: primes silenceable = pi(2^(r-d-1)) | G3: note
A4: (2, 1) | B4: ='Prime differences'!C3 -> 0 | C4: ='Composite differences'!C3 -> 1 | D4: =2^(2-1-1) -> 1 | E4: 1 to 2 | F4: 0 | G4: trivial by membership
A5: (4, 1) | B5: ='Prime differences'!C5 -> 0 | C5: ='Composite differences'!C5 -> 4 | D5: =2^(4-1-1) -> 4 | E5: 3 to 4 | F5: 2 | G5: trivial by membership
A6: (8, 3) | B6: ='Prime differences'!E9 -> 0 | C6: ='Composite differences'!E9 -> 16 | D6: =2^(8-3-1) -> 16 | E6: 5 to 8 | F6: 6 | G6: trivial by lattice: sits on r = 2d+2, where the count coprime to 6 has an exact zero
A7: (20, 6) | B7: ='Prime differences'!H21 -> 0 | C7: ='Composite differences'!H21 -> 8192 | D7: =2^(20-6-1) -> 8192 | E7: 14 to 20 | F7: 1028 | G7: trivial in neither sense
A9: The four repeats that produce them
A10: A zero at depth d is a repeat in the row at depth d-1. These are the only four in the table.
A12: depth d-1 | B12: regimes | C12: repeated value | D12: produces zero at
A13: 0 | B13: 1, 2 | C13: ='Prime differences'!B3 -> 1 | D13: (2, 1)
A14: 0 | B14: 3, 4 | C14: ='Prime differences'!B5 -> 2 | D14: (4, 1)
A15: 2 | B15: 7, 8 | C15: ='Prime differences'!D9 -> 4 | D15: (8, 3)
A16: 5 | B16: 19, 20 | C16: ='Prime differences'!G21 -> 623 | D16: (20, 6)
A18: Identity: prime cell = 0 <=> composite cell = 2^(r-d-1) <=> the zero survives exactly pi(2^(r-d-1)) silencings.
A19: Silencing radii in column F are computed values, not spreadsheet formulas; see the papers.
